Workbook
Name A: 'Ext. & Prep. Task List 1'!$B$9
Name B: 'Ext. & Prep. Task List 1'!$B$10

Sheet Ext. & Prep. Task List 1
B1: NIPT DNA Extraction & Library Preparation Task List (with fragment screening)
A4: ว/ด/ป ที่ปฏิบัติงาน | B4: DD/MM/YYYY | I4: การทดสอบ | K4: NIPT
A5: หมายเลย Task | B5: Run…......../2026 | I5: ผู้ปฏิบัติงาน
A6: แผนผังตัวอย่าง
A7: แบ่งตัวอย่าง 200 μL ลง Strip Plate ตามตน. / ตน. 1 (PC) ใส่ MilliQ
B8: Run…........ S1 | E8: ✓ | F8: Barcode | H8: Run…........S2 | K8: ✓ | L8: Barcode
A9: A | F9: 1 | L9: 9
A10: B | F10: 2 | L10: 10
A11: C | F11: 3 | L11: 11
A12: D | F12: 4 | L12: 12
A13: E | F13: 5 | L13: 13
A14: F | F14: 6 | L14: 14
A15: G | F15: 7 | L15: 15
A16: H | F16: 8 | L16: 16
A17: Extraction Lot no./Exp. Date
A18: Library Lot no./Exp. Date.
A19: ขั้นตอนการเตรียมการสกัดตัวอย่าง (Extraction)
A20: ☐ เปิดเครื่อง MGISP-100 และ Pre-clean (ประมาณ 20 นาที) ก่อนการใช้งาน (Cf-WI-T-BM18-01)
A21: Reagent preparation
A22: กล่องที่ 1/2 — วางที่ Rt เก็บให้พ้นแสง | E22: กล่องที่ 2/2 — อยู่ที่ 4°C
A23: ☐ Lysis buffer | E23: ☐ Magnetic Bead 1: วางที่อุณหภูมิห้อง 30 min | K23: ☐ Elution buffer
A24: ☐ Wash buffer 1 | E24: ☐ Magnetic Bead 2 (733 μL): วางที่อุณหภูมิห้อง 30 min
A25: ☐ Wash buffer 2: | E25: ☐ Magnetic Bead 2 (580 μL): วางที่อุณหภูมิห้อง 30 min
A26: ☐ เตรียม MilliQ (ตน. 1 ใน TL1 / ตน. 25 ใน TL2) | E26: ☐ เตรียม 75% Ethanol ตามปริมาตรที่ต้องการใช้ (Cf-WI-T-BM18-01)
A27: 96-Deepwell plate preparation
A28: ☐ แบ่งน้ำยาลงใน 96-Deepwell plate
A29: วางของตาม layout | Solution: NIFTY_Library preparation Script:NIFTY_LowThroughtput_DNAExtraction
A31: ☐ Post clean (Cf-WI-T-BM18-01)
A32: ขั้นตอนการเตรียมการเตรียมไลบารี่ตัวอย่าง (Library Preparation)
A33: ☐ DNA Fragment screening Product (ถ้า Freeze ค้างคืน): Thaw ที่ 4°C → Vortex + Spin down (P3) (ถ้าไม่ค้างคืน ข้ามข้อนี้)
A34: Reagent preparation
A35: กล่องที่ 3/3 — อยู่ที่ 4°C (ห้อง 1)
A36: ☐ Magnetic Beads: Vortex + Spin down
A37: Tube preparation
A38: ☐ แบ่ง Magnetic Beads 740 μL ลงใน screw cap 2mL(Position 5C) | F38: ☐ แบ่ง Magnetic Beads 910 μL ลงใน screw cap 2mL(Position 5D)
A39: 96-Deepwell plate preparation (ห้อง 1) | D39: กล่องที่ 1/3 — อยู่ที่ -20°C → Thaw ที่ Rt จนละลายสมบูรณ์ (ไม่ควรนานเกิน 15 นาที) (ห้อง 2)
A40: ☐ แบ่งน้ำยาลงใน 96-Deepwell plate
A41: กล่องที่ 2/3 — อยู่ที่ -20°C → Thaw ที่ Rt ไม่ควรนานเกิน 15 นาที (ห้อง 2) (อย่าลืมเปิดฟอยล์ก่อนเข้าเครื่อง)
A42: ☐ Barcode 2 strips (ต้องหยิบให้ตรงกับที่ระบุบนแผนผังตัวอย่าง → Thaw ที่ Rt | labels ตำแหน่ง barcode ข้างหลอด ให้ตรงกับตำแหน่งที่ระบุบนสลากก่อนทำการดึงสลากด้านบนออก | vortex + spin down
A43: NTC & PTC preparation (if needed)
...

Sheet Ext. & Prep. Task List 2
B1: NIPT DNA Extraction & Library Preparation Task List (with fragment screening)
A4: ว/ด/ป ที่ปฏิบัติงาน | B4: DD/MM/YYYY | I4: การทดสอบ | K4: NIPT
A5: หมายเลย Task | B5: Run…......../2026 | I5: ผู้ปฏิบัติงาน
A6: แผนผังตัวอย่าง
A7: แบ่งตัวอย่าง 200 ไมโครลิตร ลง Strip Plate ตามตน. / ตน. 25 (NC) ใส่ MilliQ
B8: Run…........ S3 | E8: ✓ | F8: Barcode | H8: Run…........S4 | K8: ✓ | L8: Barcode
A9: A | F9: 17 | L9: 25
A10: B | F10: 18 | L10: 26
A11: C | F11: 19 | L11: 27
A12: D | F12: 20 | L12: 28
A13: E | F13: 21 | L13: 29
A14: F | F14: 22 | L14: 30
A15: G | F15: 23 | L15: 31
A16: H | F16: 24 | L16: 32
A17: Extraction Lot no./Exp. Date
A18: Library Lot no./Exp. Date.
A19: ขั้นตอนการเตรียมการสกัดตัวอย่าง (Extraction)
A20: ☐ เปิดเครื่อง MGISP-100 และ Pre-clean (ประมาณ 20 นาที) ก่อนการใช้งาน (Cf-WI-T-BM18-01)
A21: Reagent preparation
A22: กล่องที่ 1/2 — วางที่ Rt เก็บให้พ้นแสง | E22: กล่องที่ 2/2 — อยู่ที่ 4°C
A23: ☐ Lysis buffer | E23: ☐ Magnetic Bead 1: วางที่อุณหภูมิห้อง 30 min | K23: ☐ Elution buffer
A24: ☐ Wash buffer 1 | E24: ☐ Magnetic Bead 2 (733 μL): วางที่อุณหภูมิห้อง 30 min
A25: ☐ Wash buffer 2: | E25: ☐ Magnetic Bead 2 (580 μL): วางที่อุณหภูมิห้อง 30 min
A26: ☐ เตรียม MilliQ (ตน. 1 ใน TL1 / ตน. 25 ใน TL2) | E26: ☐ เตรียม 75% Ethanol ตามปริมาตรที่ต้องการใช้ (Cf-WI-T-BM18-01)
A27: 96-Deepwell plate preparation
A28: ☐ แบ่งน้ำยาลงใน 96-Deepwell plate
A29: วางของตาม layout | Solution: NIFTY_Library preparation Script:NIFTY_LowThroughtput_DNAExtraction
A31: ☐ Post clean (Cf-WI-T-BM18-01)
A32: ขั้นตอนการเตรียมการไลบารี่ตัวอย่าง (Library Preparation)
A33: ☐ DNA Fragment screening Product (ถ้า Freeze ค้างคืน): Thaw ที่ 4°C → Vortex + Spin down (P3) (ถ้าไม่ค้างคืน ข้ามข้อนี้)
A34: Reagent preparation
A35: กล่องที่ 3/3 — อยู่ที่ 4°C (ห้อง 1)
A36: ☐ Magnetic Beads: Vortex + Spin down
A37: Tube preparation
A38: ☐ แบ่ง Magnetic Beads 740 μL ลงใน screw cap 2mL(Position 5C) | F38: ☐ แบ่ง Magnetic Beads 910 μL ลงใน screw cap 2mL(Position 5D)
A39: 96-Deepwell plate preparation (ห้อง 1) | D39: กล่องที่ 1/3 — อยู่ที่ -20°C → Thaw ที่ Rt จนละลายสมบูรณ์ (ไม่ควรนานเกิน 15 นาที) (ห้อง 2)
A40: ☐ แบ่งน้ำยาลงใน 96-Deepwell plate
A41: กล่องที่ 2/3 — อยู่ที่ -20°C → Thaw ที่ Rt ไม่ควรนานเกิน 15 นาที (ห้อง 2) (อย่าลืมเปิดฟอยล์ก่อนเข้าเครื่อง)
A42: ☐ Barcode 2 strips (ต้องหยิบให้ตรงกับที่ระบุบนแผนผังตัวอย่าง → Thaw ที่ Rt | labels ตำแหน่ง barcode ข้างหลอด ให้ตรงกับตำแหน่งที่ระบุบนสลากก่อนทำการดึงสลากด้านบนออก | vortex + spin down
A43: NTC & PTC preparation (if needed)
...

Sheet Ext. & Prep. Task List 3
B1: NIPT DNA Extraction & Library Preparation Task List (with fragment screening)
A4: ว/ด/ป ที่ปฏิบัติงาน | B4: DD/MM/YYYY | I4: การทดสอบ | K4: NIPT
A5: หมายเลย Task | B5: Run…......../2026 | I5: ผู้ปฏิบัติงาน
A6: แผนผังตัวอย่าง
A7: แบ่งตัวอย่าง 200 ไมโครลิตร ลง Strip Plate ตามตน. / ตน. 40 (BC) ใส่ MilliQ
B8: Run…........ S5 | E8: ✓ | F8: Barcode | H8: Run…........S6 | K8: ✓ | L8: Barcode
A9: A | F9: 33 | L9: 41
A10: B | F10: 34 | L10: 42
A11: C | F11: 35 | L11: 43
A12: D | F12: 36 | L12: 44
A13: E | F13: 37 | L13: 45
A14: F | F14: 38 | L14: 46
A15: G | F15: 39 | L15: 47
A16: H | F16: 40 | L16: 48
A17: Extraction Lot no./Exp. Date
A18: Library Lot no./Exp. Date.
A19: ขั้นตอนการเตรียมการสกัดตัวอย่าง (Extraction)
A20: ☐ เปิดเครื่อง MGISP-100 และ Pre-clean (ประมาณ 20 นาที) ก่อนการใช้งาน (Cf-WI-T-BM18-01)
A21: Reagent preparation
A22: กล่องที่ 1/2 — วางที่ Rt เก็บให้พ้นแสง | E22: กล่องที่ 2/2 — อยู่ที่ 4°C
A23: ☐ Lysis buffer | E23: ☐ Magnetic Bead 1: วางที่อุณหภูมิห้อง 30 min | K23: ☐ Elution buffer
A24: ☐ Wash buffer 1 | E24: ☐ Magnetic Bead 2 (733 μL): วางที่อุณหภูมิห้อง 30 min
A25: ☐ Wash buffer 2: | E25: ☐ Magnetic Bead 2 (580 μL): วางที่อุณหภูมิห้อง 30 min
A26: ☐ เตรียม MilliQ (ตน. 1 ใน TL1 / ตน. 25 ใน TL2) | E26: ☐ เตรียม 75% Ethanol ตามปริมาตรที่ต้องการใช้ (Cf-WI-T-BM18-01)
A27: 96-Deepwell plate preparation
A28: ☐ แบ่งน้ำยาลงใน 96-Deepwell plate
A29: วางของตาม layout | Solution: NIFTY_Library preparation Script:NIFTY_LowThroughtput_DNAExtraction
A31: ☐ Post clean (Cf-WI-T-BM18-01)
A32: ขั้นตอนการเตรียมการไลบารี่ตัวอย่าง (Library Preparation)
A33: ☐ DNA Fragment screening Product (ถ้า Freeze ค้างคืน): Thaw ที่ 4°C → Vortex + Spin down (P3) (ถ้าไม่ค้างคืน ข้ามข้อนี้)
A34: Reagent preparation
A35: กล่องที่ 3/3 — อยู่ที่ 4°C (ห้อง 1)
A36: ☐ Magnetic Beads: Vortex + Spin down
A37: Tube preparation
A38: ☐ แบ่ง Magnetic Beads 740 μL ลงใน screw cap 2mL(Position 5C) | F38: ☐ แบ่ง Magnetic Beads 910 μL ลงใน screw cap 2mL(Position 5D)
A39: 96-Deepwell plate preparation (ห้อง 1) | D39: กล่องที่ 1/3 — อยู่ที่ -20°C → Thaw ที่ Rt จนละลายสมบูรณ์ (ไม่ควรนานเกิน 15 นาที) (ห้อง 2)
A40: ☐ แบ่งน้ำยาลงใน 96-Deepwell plate
A41: กล่องที่ 2/3 — อยู่ที่ -20°C → Thaw ที่ Rt ไม่ควรนานเกิน 15 นาที (ห้อง 2) (อย่าลืมเปิดฟอยล์ก่อนเข้าเครื่อง)
A42: ☐ Barcode 2 strips (ต้องหยิบให้ตรงกับที่ระบุบนแผนผังตัวอย่าง → Thaw ที่ Rt | labels ตำแหน่ง barcode ข้างหลอด ให้ตรงกับตำแหน่งที่ระบุบนสลากก่อนทำการดึงสลากด้านบนออก | vortex + spin down
A43: NTC & PTC preparation (if needed)
...

Sheet QC measurements
C1: QC DNA Concentration
C3: ว/ด/ป ที่ปฏิบัติงาน | D3: DD/MM/YYYY | F3: ผู้ปฏิบัติงาน
A5: Sample ID | C5: Concentration (ng/ul) | D5: ขั้นตอนการเตรียมการวัดความเข้มข้น DNA Library product
A7: 1 | B7: ='Ext. & Prep. Task List 1'!$B$9 -> 0
A8: 2 | B8: ='Ext. & Prep. Task List 1'!$B$10 -> 0 | D8: 1. เตรียม Qubit tube ขนาด 0.5 mL ตามจำนวนที่ต้องการวัด
A9: 3 | B9: ='Ext. & Prep. Task List 1'!$B$11 -> 0 | D9: 2. เตรียมน้ำยา dsDNA ตามตารางดังต่อไปนี้
A10: 4 | B10: ='Ext. & Prep. Task List 1'!$B$12 -> 0 | E10: Standard | G10: ตัวอย่าง
A11: 5 | B11: ='Ext. & Prep. Task List 1'!$B$13 -> 0 | E11: Buffer (uL) | F11: Standrad 1 หรือ 2 (uL) | G11: Buffer (uL) | H11: Sample (uL)
A12: 6 | B12: ='Ext. & Prep. Task List 1'!$B$14 -> 0
A13: 7 | B13: ='Ext. & Prep. Task List 1'!$B$15 -> 0 | E13: 190 | F13: 10 | G13: 198 | H13: 2
A14: 8 | B14: ='Ext. & Prep. Task List 1'!$B$16 -> 0 | D14: 3. เริ่มจากเตรียม Standrad 1 และ 2 จากนั้น Vortex by hand ห้ามโดนก้นหลอด
A15: 9 | B15: ='Ext. & Prep. Task List 1'!$H$9 -> 0 | D15: และวัดค่ากรอกค่าที่ได้
A16: 10 | B16: ='Ext. & Prep. Task List 1'!$H$10 -> 0 | D16: Ref.Std. dsDNA
A17: 11 | B17: ='Ext. & Prep. Task List 1'!$H$11 -> 0
A18: 12 | B18: ='Ext. & Prep. Task List 1'!$H$12 -> 0 | D18: Standard 1 =
A19: 13 | B19: ='Ext. & Prep. Task List 1'!$H$13 -> 0
A20: 14 | B20: ='Ext. & Prep. Task List 1'!$H$14 -> 0 | D20: Standard 2 =
A21: 15 | B21: ='Ext. & Prep. Task List 1'!$H$15 -> 0
A22: 16 | B22: ='Ext. & Prep. Task List 1'!$H$16 -> 0 | D22: Standard 2 Conc. =…...................ng/ul (ref. 9.9 ng/uL)
A23: 17 | B23: ='Ext. & Prep. Task List 2'!$B$9 -> 0
A24: 18 | B24: ='Ext. & Prep. Task List 2'!$B$10 -> 0
A25: 19 | B25: ='Ext. & Prep. Task List 2'!$B$11 -> 0 | D25: 4. เตรียมตัวอย่าง จากนั้น Vortex by hand ห้ามโดนก้นหลอด
A26: 20 | B26: ='Ext. & Prep. Task List 2'!$B$12 -> 0 | D26: และวัดค่ากรอกค่าที่ได้ตามลำดับ
A27: 21 | B27: ='Ext. & Prep. Task List 2'!$B$13 -> 0
A28: 22 | B28: ='Ext. & Prep. Task List 2'!$B$14 -> 0
A29: 23 | B29: ='Ext. & Prep. Task List 2'!$B$15 -> 0
A30: 24 | B30: ='Ext. & Prep. Task List 2'!$B$16 -> 0
A31: 25 | B31: ='Ext. & Prep. Task List 2'!$H$9 -> 0
A32: 26 | B32: ='Ext. & Prep. Task List 2'!$H$10 -> 0 | D32: หมายเหตุ : ตัวอย่างและ Positive และ Negative control ควรมีความเข้มข้น ≥ 2 ng/ul
A33: 27 | B33: ='Ext. & Prep. Task List 2'!$H$11 -> 0 | D33: หากไม่เป็นไปตามเกณฑ์ให้เริ่มสกัดใหม่อีกครั้งในตัวอย่างที่ผ่านเกณฑ์
A34: 28 | B34: ='Ext. & Prep. Task List 2'!$H$12 -> 0 | D34: Blank control ควรมีความเข้มข้น ≤ 0.6 ng/ul
A35: 29 | B35: ='Ext. & Prep. Task List 2'!$H$13 -> 0
A36: 30 | B36: ='Ext. & Prep. Task List 2'!$H$14 -> 0
A37: 31 | B37: ='Ext. & Prep. Task List 2'!$H$15 -> 0
A38: 32 | B38: ='Ext. & Prep. Task List 2'!$H$16 -> 0
A39: 33 | B39: ='Ext. & Prep. Task List 3'!$B$9 -> 0
A40: 34 | B40: ='Ext. & Prep. Task List 3'!$B$10 -> 0
A41: 35 | B41: ='Ext. & Prep. Task List 3'!$B$11 -> 0
A42: 36 | B42: ='Ext. & Prep. Task List 3'!$B$12 -> 0
A43: 37 | B43: ='Ext. & Prep. Task List 3'!$B$13 -> 0
...

Sheet Pooling Table
B1: Pooling Table
B3: ว/ด/ป ที่ปฏิบัติงาน | C3: DD/MM/YYYY | D3: ผู้ปฏิบัติงาน
A6: Pooling amount (pmol) | B6: 16 | D6: Ref.Std. dsDNA
A7: Sample ID | B7: Volume (ul) | C7: Total sample volume (ul)
A8: ='Ext. & Prep. Task List 1'!$B$9 -> 0 | B8: =IF('QC measurements'!C7="","",(160/COUNTA('QC measurements'!$C$7:$C$54)*$B$6/'QC measurements'!C7)) | C8: =SUM(B8:B55) -> 0 | D8: Standard 1 =
A9: ='Ext. & Prep. Task List 1'!$B$10 -> 0 | B9: =IF('QC measurements'!C8="","",(160/COUNTA('QC measurements'!$C$7:$C$54)*$B$6/'QC measurements'!C8)) | C9: Desired Total Volume (ul)
A10: ='Ext. & Prep. Task List 1'!$B$11 -> 0 | B10: =IF('QC measurements'!C9="","",(160/COUNTA('QC measurements'!$C$7:$C$54)*$B$6/'QC measurements'!C9)) | C10: =48*B6 -> 768 | D10: Standard 2 =
A11: ='Ext. & Prep. Task List 1'!$B$12 -> 0 | B11: =IF('QC measurements'!C10="","",(160/COUNTA('QC measurements'!$C$7:$C$54)*$B$6/'QC measurements'!C10)) | C11: EB volume (ul)
A12: ='Ext. & Prep. Task List 1'!$B$13 -> 0 | B12: =IF('QC measurements'!C11="","",(160/COUNTA('QC measurements'!$C$7:$C$54)*$B$6/'QC measurements'!C11)) | C12: =C10-C8 -> 768 | D12: Standard 2 Conc. =…...................ng/ul (ref. 9.9 ng/uL)
A13: ='Ext. & Prep. Task List 1'!$B$14 -> 0 | B13: =IF('QC measurements'!C12="","",(160/COUNTA('QC measurements'!$C$7:$C$54)*$B$6/'QC measurements'!C12))
A14: ='Ext. & Prep. Task List 1'!$B$15 -> 0 | B14: =IF('QC measurements'!C13="","",(160/COUNTA('QC measurements'!$C$7:$C$54)*$B$6/'QC measurements'!C13)) | C14: Pool Library concentration (ng/μl)
A15: ='Ext. & Prep. Task List 1'!$B$16 -> 0 | B15: =IF('QC measurements'!C14="","",(160/COUNTA('QC measurements'!$C$7:$C$54)*$B$6/'QC measurements'!C14)) | C15: เกณฑ์การยอมรับ 3.00-3.60 ng/ul
A16: ='Ext. & Prep. Task List 1'!$H$9 -> 0 | B16: =IF('QC measurements'!C15="","",(160/COUNTA('QC measurements'!$C$7:$C$54)*$B$6/'QC measurements'!C15)) | C16: เปิดเครื่อง MGISP-100 และ Pre-clean (ประมาณ 20 นาที) ก่อนการใช้งาน
A17: ='Ext. & Prep. Task List 1'!$H$10 -> 0 | B17: =IF('QC measurements'!C16="","",(160/COUNTA('QC measurements'!$C$7:$C$54)*$B$6/'QC measurements'!C16)) | C17: ขั้นตอนการเตรียมการ Pooling DNA Library
A18: ='Ext. & Prep. Task List 1'!$H$11 -> 0 | B18: =IF('QC measurements'!C17="","",(160/COUNTA('QC measurements'!$C$7:$C$54)*$B$6/'QC measurements'!C17))
A19: ='Ext. & Prep. Task List 1'!$H$12 -> 0 | B19: =IF('QC measurements'!C18="","",(160/COUNTA('QC measurements'!$C$7:$C$54)*$B$6/'QC measurements'!C18)) | C19: 1. นำตัวอย่าง DNA library product ออกมาละลาย หลังจากนั้น Vortex และ Spindown
A20: ='Ext. & Prep. Task List 1'!$H$13 -> 0 | B20: =IF('QC measurements'!C19="","",(160/COUNTA('QC measurements'!$C$7:$C$54)*$B$6/'QC measurements'!C19)) | C20: 2. เมื่อได้ปริมาตรในการ Pooling ของแต่ละตัวอย่าง ให้นำไปกรอกใน ไฟล์ .CSV
A21: ='Ext. & Prep. Task List 1'!$H$14 -> 0 | B21: =IF('QC measurements'!C20="","",(160/COUNTA('QC measurements'!$C$7:$C$54)*$B$6/'QC measurements'!C20)) | C21: ที่ใช้สำหรับลงเครื่อง SP100
A22: ='Ext. & Prep. Task List 1'!$H$15 -> 0 | B22: =IF('QC measurements'!C21="","",(160/COUNTA('QC measurements'!$C$7:$C$54)*$B$6/'QC measurements'!C21)) | C22: 3.เติม Elution buffer ตามปริมาตรที่ปรากฏในช่อง EB volume (ul)
A23: ='Ext. & Prep. Task List 1'!$H$16 -> 0 | B23: =IF('QC measurements'!C22="","",(160/COUNTA('QC measurements'!$C$7:$C$54)*$B$6/'QC measurements'!C22)) | C23: ลงใน screw cap ขนาด 2 mL
A24: ='Ext. & Prep. Task List 2'!$B$9 -> 0 | B24: =IF('QC measurements'!C23="","",(160/COUNTA('QC measurements'!$C$7:$C$54)*$B$6/'QC measurements'!C23)) | C24: 4. จัดเรียงอุปกรณ์ ตามหน้า Layout ขั้นตอนการ Pooling บนเครื่อง SP100 เริ่มการทำงาน
A25: ='Ext. & Prep. Task List 2'!$B$10 -> 0 | B25: =IF('QC measurements'!C24="","",(160/COUNTA('QC measurements'!$C$7:$C$54)*$B$6/'QC measurements'!C24)) | C25: 5. หลังจากการ Pooling DNA Library ทำการวัดความเข้มข้นด้วย น้ำยา dsDNA
A26: ='Ext. & Prep. Task List 1'!$B$11 -> 0 | B26: =IF('QC measurements'!C25="","",(160/COUNTA('QC measurements'!$C$7:$C$54)*$B$6/'QC measurements'!C25)) | C26: 6. เตรียมน้ำยา dsDNA ตามตารางดังต่อไปนี้
A27: ='Ext. & Prep. Task List 2'!$B$12 -> 0 | B27: =IF('QC measurements'!C26="","",(160/COUNTA('QC measurements'!$C$7:$C$54)*$B$6/'QC measurements'!C26)) | C27: Standard | E27: ตัวอย่าง
A28: ='Ext. & Prep. Task List 2'!$B$13 -> 0 | B28: =IF('QC measurements'!C27="","",(160/COUNTA('QC measurements'!$C$7:$C$54)*$B$6/'QC measurements'!C27)) | C28: Buffer (uL) | D28: Standrad 1 หรือ 2 (uL) | E28: Buffer (uL) | F28: Sample (uL)
A29: ='Ext. & Prep. Task List 2'!$B$14 -> 0 | B29: =IF('QC measurements'!C28="","",(160/COUNTA('QC measurements'!$C$7:$C$54)*$B$6/'QC measurements'!C28))
A30: ='Ext. & Prep. Task List 2'!$B$15 -> 0 | B30: =IF('QC measurements'!C29="","",(160/COUNTA('QC measurements'!$C$7:$C$54)*$B$6/'QC measurements'!C29)) | C30: 190 | D30: 10 | E30: 198 | F30: 2
A31: ='Ext. & Prep. Task List 2'!$B$16 -> 0 | B31: =IF('QC measurements'!C30="","",(160/COUNTA('QC measurements'!$C$7:$C$54)*$B$6/'QC measurements'!C30)) | C31: 190 | D31: 10 | E31: 198 | F31: 2
A32: ='Ext. & Prep. Task List 2'!$H$9 -> 0 | B32: =IF('QC measurements'!C31="","",(160/COUNTA('QC measurements'!$C$7:$C$54)*$B$6/'QC measurements'!C31)) | C32: 7. เริ่มจากเตรียม Standrad 1 และ 2 จากนั้น Vortex by hand ห้ามโดนก้นหลอด
A33: ='Ext. & Prep. Task List 2'!$H$10 -> 0 | B33: =IF('QC measurements'!C32="","",(160/COUNTA('QC measurements'!$C$7:$C$54)*$B$6/'QC measurements'!C32)) | C33: และวัดค่ากรอกค่าที่ได้
A34: ='Ext. & Prep. Task List 2'!$H$11 -> 0 | B34: =IF('QC measurements'!C33="","",(160/COUNTA('QC measurements'!$C$7:$C$54)*$B$6/'QC measurements'!C33)) | C34: 8. เตรียมตัวอย่าง จากนั้น Vortex by hand ห้ามโดนก้นหลอด
A35: ='Ext. & Prep. Task List 2'!$H$12 -> 0 | B35: =IF('QC measurements'!C34="","",(160/COUNTA('QC measurements'!$C$7:$C$54)*$B$6/'QC measurements'!C34)) | C35: และวัดค่ากรอกค่าที่ได้ ในช่อง Pool Library concentration (ng/μl)
A36: ='Ext. & Prep. Task List 2'!$H$13 -> 0 | B36: =IF('QC measurements'!C35="","",(160/COUNTA('QC measurements'!$C$7:$C$54)*$B$6/'QC measurements'!C35))
A37: ='Ext. & Prep. Task List 2'!$H$14 -> 0 | B37: =IF('QC measurements'!C36="","",(160/COUNTA('QC measurements'!$C$7:$C$54)*$B$6/'QC measurements'!C36)) | C37: หมายเหตุ : เกณฑ์ของความเข้มข้น Pooling DNA Library คือ 3.00-3.60 ng/ul
A38: ='Ext. & Prep. Task List 2'!$H$15 -> 0 | B38: =IF('QC measurements'!C37="","",(160/COUNTA('QC measurements'!$C$7:$C$54)*$B$6/'QC measurements'!C37))
A39: ='Ext. & Prep. Task List 2'!$H$16 -> 0 | B39: =IF('QC measurements'!C38="","",(160/COUNTA('QC measurements'!$C$7:$C$54)*$B$6/'QC measurements'!C38))
A40: ='Ext. & Prep. Task List 3'!$B$9 -> 0 | B40: =IF('QC measurements'!C39="","",(160/COUNTA('QC measurements'!$C$7:$C$54)*$B$6/'QC measurements'!C39))
A41: ='Ext. & Prep. Task List 3'!$B$10 -> 0 | B41: =IF('QC measurements'!C40="","",(160/COUNTA('QC measurements'!$C$7:$C$54)*$B$6/'QC measurements'!C40))
A42: ='Ext. & Prep. Task List 3'!$B$11 -> 0 | B42: =IF('QC measurements'!C41="","",(160/COUNTA('QC measurements'!$C$7:$C$54)*$B$6/'QC measurements'!C41))
A43: ='Ext. & Prep. Task List 3'!$B$12 -> 0 | B43: =IF('QC measurements'!C42="","",(160/COUNTA('QC measurements'!$C$7:$C$54)*$B$6/'QC measurements'!C42))
...

Sheet Seq Task-G50
A1: DNBSEQ-G50 Sequencing Record
A4: ว/ด/ป ที่ปฏิบัติงาน | C4: ผู้ปฏิบัติงาน | E4: DNBSEQ-G50 no.: | F4: 1 | G4: Barcode type: | H4: 10
A5: เปิดเครื่อง MGISP-100 และ Pre-clean (ประมาณ 20 นาที) ก่อนการใช้งาน
A6: ขั้นตอนการเตรียมการทำ DNB
A7: Reagent preparation | B7: 1.นำ Sequencing cartridge ออกจาก ชุด Universal Sequencing Reaction เก็บที่อุณหภูมิ -20⁰C มาละลายที่ 4⁰C ข้ามคืน หรือ แช่น้ำจะกว่าจะละลายโดยสมบูรณ์
B8: หากยังไม่ใช้งานทันที่ให้เก็บที่อุณหภูมิ 4⁰C (ห้ามนำ Sequencing cartridge ที่ละลายไม่สมบูรณ์มาใช้งาน)
B9: 2. นำ cyclization Buffer, Make DNB Buffer, DNB Enzyme Mix I, Stop DNB Reaction buffer, DNB Load buffer I, DNB Load buffer II, Low TE, dNTPs Mix II, dNTPs Mix III ออกจาก ชุด Universal Sequencing Reaction เก็บที่อุณหภูมิ -20⁰C มาละลายที่ 4⁰C หลังจากนั้น Vortex และ Spindown
B10: 3 เตรียม Cyclization mix (2 rxn) | C10: Cyclization buffer (μL) | D10: 27.8 | E10: Ligase (μL) | F10: 1.2 | G10: ลงใน screw cap ขนาด 0.5 mL on ice
A11: Sample preparation | B11: 4. Vortex และ Spindown ตัวอย่าง Pooling DNA Library แบ่งใส่ break away plate โดย pool ที่ 1 จะเริ่มต้นที่ 1A เสมอ ปริมาตร 48 ul
B12: 5. นำ DNB Enzyme Mix II (LC) และ Ligase ออกจาก ชุด Universal Sequencing Reaction เก็บที่อุณหภูมิ -20⁰C ทำการ spin down (เก็บ enzymeไว้บน Ice box)
B13: 6. จัดเรียงอุปกรณ์ ตามหน้า Layout ขั้นตอนการ Pooling บนเครื่อง SP100 เริ่มการทำงาน กรอกค่าที่ SP 100 ถาม DNB 1 pool และเวลาที่ใช้ RCA 25 min เมื่อเสร็จงานทำการ Post clean ตามที่เครื่อง SP100 แนะนำ
A14: QC measurements | B14: 7.เตรียมน้ำยา ssDNA mix ตามตารางดังต่อไปนี้ (ต่อ 1 rxn) | D14: Fluorescent Dye ( uL) | E14: 1 | F14: Buffer ( uL) | G14: 199
B15: 8. เริ่มจากเตรียม Standrad 1 และ 2 จากนั้น Vortex by hand ห้ามโดนก้นหลอด และวัดค่ากรอกค่าที่ได้
B16: ssDNA mix (uL) | C16: 190 | D16: Standrad 1 หรือ 2 (uL) | E16: 10
B17: Ref.Std. dsDNA | C17: Standard 1 = | D17: Standard 2 = | E17: Standard 2 Conc. =…...................ng/ul (ref. 19.9 ng/uL)
B19: 9. เตรียมตัวอย่าง จากนั้น Vortex by hand ห้ามโดนก้นหลอด
B20: ssDNA mix (uL) | C20: 198 | D20: Sample (uL) | E20: 2
B21: DNB concentration (ng/uL)
B22: (Ref. 8-50 ng/uL)
A23: DNB preparation | B23: DNB Load Buffer 1 (μL) ชุด Universal Sequencing Reaction เก็บที่อุณหภูมิ -20°C | C23: DNB Load Buffer 2(μL) ชุด Universal Sequencing Reaction เก็บที่อุณหภูมิ -20°C | D23: Make DNB Enzyme II (μL) ชุด Universal Sequencing Reaction เก็บที่อุณหภูมิ -20°C | E23: Volume of DNB added (μL) | F23: ลงใน screw cap ขนาด 0.5 mL ใช้ wide Bore tip ในการผสม DNB
B24: 50 | C24: 50 | D24: 1 | E24: 100
A25: Cartridge preparation | B25: Sequencing chip positioned firmly ( ) | F25: Confirm（√）
B26: Sequencing reagent preparation | C26: Reagent Name | D26: Position | E26: Volume（μL）
C27: dNTPs mix III | D27: 1 | E27: 320
C28: dNTPs mix II | D28: 2 | E28: 560
C29: Sequencing enzyme mix | D29: 1 | E29: 320
C30: Sequencing enzyme mix | D30: 2 | E30: 280
A31: ขั้นตอนการ Sequencing
A33: Lane | B33: DNB ID | D33: Sequencing Type | E33: Cycle number | F33: Barcode information | H33: Project type
A34: ① | B34: DNBYYYYMMDD | D34: SE | E34: 35+10 | F34: 1-128 | H34: NIPT
A35: 1. ล้างเครื่องก่อนใช้งานตามมาตรฐาน
A36: 2. ก่อนรันเช็คพื้นที่ของ drive D จดค่า ควรมากกว่า 500 GB | D36: Hard Drive Memory (TB):
A37: 3. เมื่อเตรียมตัวอย่าง DNB และ cartridge เรียบร้อย นำมาเข้าเครื่อง G50 ทำตามขั้นตอนที่เครื่องสั่ง และจดค่าความดันที่เครื่องทำได้ในขณะใส่ Flow cell | F37: Negative Pressure (kPa):
A39: First Cycle:
A40: lane | B40: Base/Fluorescent Intensity (K)
A41: ① | B41: Loaded DNB | D41: Q30% | E41: BIC | G41: Fit
A42: ค่าที่ได้
